Workbook
Name Curs: 'Lista de prețuri'!$F$3
Name CotaTVA: 'Ofertă comercială'!$F$9

Sheet Lista de prețuri
C1: LISTA DE PREȚURI
C2: Tehnică agricolă Shaktiman
C3: Prețuri în EUR, fără TVA | E3: Curs EUR/MDL: | F3: 20.1 | G3: Actualizat: 13.10.2026
A4: Nr. | B4: Foto | C4: Denumire produs | D4: Preț EUR (fără TVA) | E4: Preț promo EUR | F4: Preț MDL* (fără TVA) | G4: Notă | H4: Pagina produsului | I4: Ofertă comercială
A5: TOCĂTOARE DE RESTURI VEGETALE · 27 modele
A6: 1 | C6: Tocător lateral Shaktiman AFM 160 | D6: 4900 | F6: =IF(ISNUMBER(E6),ROUND(E6*Curs,0),IF(ISNUMBER(D6),ROUND(D6*Curs,0),"La cerere")) | H6: Vezi pe site | I6: Deschide oferta
A7: 2 | C7: Tocător lateral Shaktiman AFM 180 | D7: 5200 | F7: =IF(ISNUMBER(E7),ROUND(E7*Curs,0),IF(ISNUMBER(D7),ROUND(D7*Curs,0),"La cerere")) | H7: Vezi pe site | I7: Deschide oferta
A8: 3 | C8: Tocător serie medie Shaktiman BMF 1.45 | D8: 2800 | F8: =IF(ISNUMBER(E8),ROUND(E8*Curs,0),IF(ISNUMBER(D8),ROUND(D8*Curs,0),"La cerere")) | H8: Vezi pe site | I8: Deschide oferta
A9: 4 | C9: Tocător serie medie Shaktiman BMF 1.60 | D9: 3200 | F9: =IF(ISNUMBER(E9),ROUND(E9*Curs,0),IF(ISNUMBER(D9),ROUND(D9*Curs,0),"La cerere")) | H9: Vezi pe site | I9: Deschide oferta
A10: 5 | C10: Tocător serie medie Shaktiman BMF 1.80 | D10: 3400 | F10: =IF(ISNUMBER(E10),ROUND(E10*Curs,0),IF(ISNUMBER(D10),ROUND(D10*Curs,0),"La cerere")) | H10: Vezi pe site | I10: Deschide oferta
A11: 6 | C11: Tocător serie medie Shaktiman BMF 2.00 | D11: 3600 | F11: =IF(ISNUMBER(E11),ROUND(E11*Curs,0),IF(ISNUMBER(D11),ROUND(D11*Curs,0),"La cerere")) | H11: Vezi pe site | I11: Deschide oferta
A12: 7 | C12: Tocător serie medie Shaktiman BMF 2.20 | D12: 4000 | F12: =IF(ISNUMBER(E12),ROUND(E12*Curs,0),IF(ISNUMBER(D12),ROUND(D12*Curs,0),"La cerere")) | H12: Vezi pe site | I12: Deschide oferta
A13: 8 | C13: Tocător serie grea Shaktiman BPF 1.60 | D13: 4000 | F13: =IF(ISNUMBER(E13),ROUND(E13*Curs,0),IF(ISNUMBER(D13),ROUND(D13*Curs,0),"La cerere")) | H13: Vezi pe site | I13: Deschide oferta
A14: 9 | C14: Tocător serie grea Shaktiman BPF 1.80 | D14: 4200 | F14: =IF(ISNUMBER(E14),ROUND(E14*Curs,0),IF(ISNUMBER(D14),ROUND(D14*Curs,0),"La cerere")) | H14: Vezi pe site | I14: Deschide oferta
A15: 10 | C15: Tocător serie grea Shaktiman BPF 2.00 | D15: 4400 | F15: =IF(ISNUMBER(E15),ROUND(E15*Curs,0),IF(ISNUMBER(D15),ROUND(D15*Curs,0),"La cerere")) | H15: Vezi pe site | I15: Deschide oferta
A16: 11 | C16: Tocător serie grea Shaktiman BPF 2.80 | D16: 5800 | F16: =IF(ISNUMBER(E16),ROUND(E16*Curs,0),IF(ISNUMBER(D16),ROUND(D16*Curs,0),"La cerere")) | H16: Vezi pe site | I16: —
A17: 12 | C17: Tocător cu ridicare Shaktiman SPFM 1.55M | D17: 4600 | F17: =IF(ISNUMBER(E17),ROUND(E17*Curs,0),IF(ISNUMBER(D17),ROUND(D17*Curs,0),"La cerere")) | H17: Vezi pe site | I17: Deschide oferta
... A20: 15 | C20: Tocător serie ultra-ușoară Shaktiman BMA 135 | D20: 1200 | F20: =IF(ISNUMBER(E20),ROUND(E20*Curs,0),IF(ISNUMBER(D20),ROUND(D20*Curs,0),"La cerere")) | H20: Vezi pe site | I20: Deschide oferta
A21: 16 | C21: Tocător serie ultra-ușoară Shaktiman BMA 115 | D21: La cerere | F21: =IF(ISNUMBER(E21),ROUND(E21*Curs,0),IF(ISNUMBER(D21),ROUND(D21*Curs,0),"La cerere")) | H21: Vezi pe site | I21: Deschide oferta
A22: 17 | C22: Tocător serie ușoară Shaktiman SFM-L 0.85 | D22: 1100 | F22: =IF(ISNUMBER(E22),ROUND(E22*Curs,0),IF(ISNUMBER(D22),ROUND(D22*Curs,0),"La cerere")) | H22: Vezi pe site | I22: —
A23: 18 | C23: Tocător serie ușoară Shaktiman SFM-L 1.05 | D23: 1300 | F23: =IF(ISNUMBER(E23),ROUND(E23*Curs,0),IF(ISNUMBER(D23),ROUND(D23*Curs,0),"La cerere")) | H23: Vezi pe site | I23: —
A24: 19 | C24: Tocător serie ușoară Shaktiman SFM-L 1.25 | D24: 1400 | F24: =IF(ISNUMBER(E24),ROUND(E24*Curs,0),IF(ISNUMBER(D24),ROUND(D24*Curs,0),"La cerere")) | H24: Vezi pe site | I24: Deschide oferta
A25: 20 | C25: Tocător serie ușoară Shaktiman SFM-L 1.45 | D25: 1600 | F25: =IF(ISNUMBER(E25),ROUND(E25*Curs,0),IF(ISNUMBER(D25),ROUND(D25*Curs,0),"La cerere")) | H25: Vezi pe site | I25: Deschide oferta
A26: 21 | C26: Tocător serie ușoară Shaktiman SFM-L 1.65 | D26: 1800 | F26: =IF(ISNUMBER(E26),ROUND(E26*Curs,0),IF(ISNUMBER(D26),ROUND(D26*Curs,0),"La cerere")) | H26: Vezi pe site | I26: Deschide oferta
A27: 22 | C27: Tocător serie semi-ușoară Shaktiman SFM 130 | D27: 2300 | F27: =IF(ISNUMBER(E27),ROUND(E27*Curs,0),IF(ISNUMBER(D27),ROUND(D27*Curs,0),"La cerere")) | H27: Vezi pe site | I27: Deschide oferta
A28: 23 | C28: Tocător serie semi-ușoară Shaktiman SFM 145 | D28: 2450 | F28: =IF(ISNUMBER(E28),ROUND(E28*Curs,0),IF(ISNUMBER(D28),ROUND(D28*Curs,0),"La cerere")) | H28: Vezi pe site | I28: Deschide oferta
A29: 24 | C29: Tocător serie semi-ușoară Shaktiman SFM 160 | D29: 2550 | F29: =IF(ISNUMBER(E29),ROUND(E29*Curs,0),IF(ISNUMBER(D29),ROUND(D29*Curs,0),"La cerere")) | H29: Vezi pe site | I29: Deschide oferta
A30: 25 | C30: Tocător serie semi-ușoară Shaktiman SFM 175 | D30: 2850 | F30: =IF(ISNUMBER(E30),ROUND(E30*Curs,0),IF(ISNUMBER(D30),ROUND(D30*Curs,0),"La cerere")) | H30: Vezi pe site | I30: Deschide oferta
A31: 26 | C31: Tocător serie semi-ușoară Shaktiman SFM 220 | D31: 3100 | F31: =IF(ISNUMBER(E31),ROUND(E31*Curs,0),IF(ISNUMBER(D31),ROUND(D31*Curs,0),"La cerere")) | H31: Vezi pe site | I31: Deschide oferta
A32: 27 | C32: Tocător de furaje verzi / crengi Shaktiman 12 SM | D32: 3500 | F32: =IF(ISNUMBER(E32),ROUND(E32*Curs,0),IF(ISNUMBER(D32),ROUND(D32*Curs,0),"La cerere")) | H32: Vezi pe site | I32: Deschide oferta
A33: FREZE DE SOL · 22 modele
A34: 28 | C34: Freză rotativă Shaktiman Mini Plus 100 | D34: 1050 | F34: =IF(ISNUMBER(E34),ROUND(E34*Curs,0),IF(ISNUMBER(D34),ROUND(D34*Curs,0),"La cerere")) | H34: Vezi pe site | I34: Deschide oferta
A35: 29 | C35: Freză rotativă Shaktiman Mini Plus 120 | D35: 1200 | F35: =IF(ISNUMBER(E35),ROUND(E35*Curs,0),IF(ISNUMBER(D35),ROUND(D35*Curs,0),"La cerere")) | H35: Vezi pe site | I35: Deschide oferta
A36: 30 | C36: Freză rotativă serie ușoară Shaktiman UL 36 | D36: 1300 | F36: =IF(ISNUMBER(E36),ROUND(E36*Curs,0),IF(ISNUMBER(D36),ROUND(D36*Curs,0),"La cerere")) | H36: Vezi pe site | I36: Deschide oferta
A37: 31 | C37: Freză rotativă serie ușoară Shaktiman UL 42 | D37: 1500 | F37: =IF(ISNUMBER(E37),ROUND(E37*Curs,0),IF(ISNUMBER(D37),ROUND(D37*Curs,0),"La cerere")) | H37: Vezi pe site | I37: Deschide oferta
A38: 32 | C38: Freză rotativă serie medie Shaktiman UM 53 | D38: 1650 | F38: =IF(ISNUMBER(E38),ROUND(E38*Curs,0),IF(ISNUMBER(D38),ROUND(D38*Curs,0),"La cerere")) | H38: Vezi pe site | I38: Deschide oferta
A39: 33 | C39: Freză rotativă serie medie Shaktiman UM 56 | D39: 1750 | F39: =IF(ISNUMBER(E39),ROUND(E39*Curs,0),IF(ISNUMBER(D39),ROUND(D39*Curs,0),"La cerere")) | H39: Vezi pe site | I39: Deschide oferta
A40: 34 | C40: Freză rotativă serie medie Shaktiman UM 60 | D40: 1900 | F40: =IF(ISNUMBER(E40),ROUND(E40*Curs,0),IF(ISNUMBER(D40),ROUND(D40*Curs,0),"La cerere")) | H40: Vezi pe site | I40: Deschide oferta
A41: 35 | C41: Freză rotativă serie medie Shaktiman UM 70 | D41: 2000 | F41: =IF(ISNUMBER(E41),ROUND(E41*Curs,0),IF(ISNUMBER(D41),ROUND(D41*Curs,0),"La cerere")) | H41: Vezi pe site | I41: Deschide oferta
A42: 36 | C42: Freză rotativă serie grea Shaktiman Semi Champion 190 | D42: 2100 | F42: =IF(ISNUMBER(E42),ROUND(E42*Curs,0),IF(ISNUMBER(D42),ROUND(D42*Curs,0),"La cerere")) | H42: Vezi pe site | I42: Deschide oferta
...

Sheet Ofertă comercială
D1: „Ozonteh Impex” SRL
D2: MD-3701, mun. Strășeni, șos. Chișinău 69, Republica Moldova
D3: C.F. 1013600012644 · Cod TVA 8600854
D4: office@ozonteh.md · ozonteh.net
A7: OFERTĂ COMERCIALĂ
B8: Nr. ofertei: | E8: Data: | G8: Valabilă (zile): | H8: 14
B9: Curs EUR/MDL: | C9: =Curs | E9: Cota TVA: | F9: 0.2 | G9: Expiră la: | H9: =IF(ISNUMBER(F8),F8+H8,"")
A11: DATE CLIENT
B12: Client / companie:
B13: Persoană de contact:
B14: Telefon: | E14: E-mail:
B15: Localitate / adresă:
A17: PRODUSE OFERITE
A18: Nr. | B18: Produs (alegeți din listă) | C18: Pagina produsului | D18: Cant. | E18: Preț unitar EUR fără TVA | F18: Reducere % | G18: Total EUR fără TVA | H18: Total MDL fără TVA | I18: Link ofertă produs (pentru meniul Ozonteh)
A19: =IF(B19="","",ROW()-18) | B19: Tocător lateral Shaktiman AFM 160 | C19: =IF(B19="","",IFERROR(HYPERLINK(INDEX(Catalog!$B$2:$B$70,MATCH(B19,Catalog!$A$2:$A$70,0)),"Vezi produs"),"")) | D19: 1 | E19: =IF(B19="","",IFERROR(INDEX(Catalog!$C$2:$C$70,MATCH(B19,Catalog!$A$2:$A$70,0)),"nu e în listă")) | G19: =IF(AND(ISNUMBER(D19),ISNUMBER(E19)),ROUND(D19*E19*(1-N(F19)),2),"") | H19: =IF(ISNUMBER(G19),ROUND(G19*$C$9,0),"") | I19: =IF(B19="","",IFERROR(INDEX(Catalog!$F$2:$F$70,MATCH(B19,Catalog!$A$2:$A$70,0))&"",""))
A20: =IF(B20="","",ROW()-18) | C20: =IF(B20="","",IFERROR(HYPERLINK(INDEX(Catalog!$B$2:$B$70,MATCH(B20,Catalog!$A$2:$A$70,0)),"Vezi produs"),"")) | E20: =IF(B20="","",IFERROR(INDEX(Catalog!$C$2:$C$70,MATCH(B20,Catalog!$A$2:$A$70,0)),"nu e în listă")) | G20: =IF(AND(ISNUMBER(D20),ISNUMBER(E20)),ROUND(D20*E20*(1-N(F20)),2),"") | H20: =IF(ISNUMBER(G20),ROUND(G20*$C$9,0),"") | I20: =IF(B20="","",IFERROR(INDEX(Catalog!$F$2:$F$70,MATCH(B20,Catalog!$A$2:$A$70,0))&"",""))
A21: =IF(B21="","",ROW()-18) | C21: =IF(B21="","",IFERROR(HYPERLINK(INDEX(Catalog!$B$2:$B$70,MATCH(B21,Catalog!$A$2:$A$70,0)),"Vezi produs"),"")) | E21: =IF(B21="","",IFERROR(INDEX(Catalog!$C$2:$C$70,MATCH(B21,Catalog!$A$2:$A$70,0)),"nu e în listă")) | G21: =IF(AND(ISNUMBER(D21),ISNUMBER(E21)),ROUND(D21*E21*(1-N(F21)),2),"") | H21: =IF(ISNUMBER(G21),ROUND(G21*$C$9,0),"") | I21: =IF(B21="","",IFERROR(INDEX(Catalog!$F$2:$F$70,MATCH(B21,Catalog!$A$2:$A$70,0))&"",""))
A22: =IF(B22="","",ROW()-18) | C22: =IF(B22="","",IFERROR(HYPERLINK(INDEX(Catalog!$B$2:$B$70,MATCH(B22,Catalog!$A$2:$A$70,0)),"Vezi produs"),"")) | E22: =IF(B22="","",IFERROR(INDEX(Catalog!$C$2:$C$70,MATCH(B22,Catalog!$A$2:$A$70,0)),"nu e în listă")) | G22: =IF(AND(ISNUMBER(D22),ISNUMBER(E22)),ROUND(D22*E22*(1-N(F22)),2),"") | H22: =IF(ISNUMBER(G22),ROUND(G22*$C$9,0),"") | I22: =IF(B22="","",IFERROR(INDEX(Catalog!$F$2:$F$70,MATCH(B22,Catalog!$A$2:$A$70,0))&"",""))
A23: =IF(B23="","",ROW()-18) | C23: =IF(B23="","",IFERROR(HYPERLINK(INDEX(Catalog!$B$2:$B$70,MATCH(B23,Catalog!$A$2:$A$70,0)),"Vezi produs"),"")) | E23: =IF(B23="","",IFERROR(INDEX(Catalog!$C$2:$C$70,MATCH(B23,Catalog!$A$2:$A$70,0)),"nu e în listă")) | G23: =IF(AND(ISNUMBER(D23),ISNUMBER(E23)),ROUND(D23*E23*(1-N(F23)),2),"") | H23: =IF(ISNUMBER(G23),ROUND(G23*$C$9,0),"") | I23: =IF(B23="","",IFERROR(INDEX(Catalog!$F$2:$F$70,MATCH(B23,Catalog!$A$2:$A$70,0))&"",""))
A24: =IF(B24="","",ROW()-18) | C24: =IF(B24="","",IFERROR(HYPERLINK(INDEX(Catalog!$B$2:$B$70,MATCH(B24,Catalog!$A$2:$A$70,0)),"Vezi produs"),"")) | E24: =IF(B24="","",IFERROR(INDEX(Catalog!$C$2:$C$70,MATCH(B24,Catalog!$A$2:$A$70,0)),"nu e în listă")) | G24: =IF(AND(ISNUMBER(D24),ISNUMBER(E24)),ROUND(D24*E24*(1-N(F24)),2),"") | H24: =IF(ISNUMBER(G24),ROUND(G24*$C$9,0),"") | I24: =IF(B24="","",IFERROR(INDEX(Catalog!$F$2:$F$70,MATCH(B24,Catalog!$A$2:$A$70,0))&"",""))
A25: =IF(B25="","",ROW()-18) | C25: =IF(B25="","",IFERROR(HYPERLINK(INDEX(Catalog!$B$2:$B$70,MATCH(B25,Catalog!$A$2:$A$70,0)),"Vezi produs"),"")) | E25: =IF(B25="","",IFERROR(INDEX(Catalog!$C$2:$C$70,MATCH(B25,Catalog!$A$2:$A$70,0)),"nu e în listă")) | G25: =IF(AND(ISNUMBER(D25),ISNUMBER(E25)),ROUND(D25*E25*(1-N(F25)),2),"") | H25: =IF(ISNUMBER(G25),ROUND(G25*$C$9,0),"") | I25: =IF(B25="","",IFERROR(INDEX(Catalog!$F$2:$F$70,MATCH(B25,Catalog!$A$2:$A$70,0))&"",""))
A26: =IF(B26="","",ROW()-18) | C26: =IF(B26="","",IFERROR(HYPERLINK(INDEX(Catalog!$B$2:$B$70,MATCH(B26,Catalog!$A$2:$A$70,0)),"Vezi produs"),"")) | E26: =IF(B26="","",IFERROR(INDEX(Catalog!$C$2:$C$70,MATCH(B26,Catalog!$A$2:$A$70,0)),"nu e în listă")) | G26: =IF(AND(ISNUMBER(D26),ISNUMBER(E26)),ROUND(D26*E26*(1-N(F26)),2),"") | H26: =IF(ISNUMBER(G26),ROUND(G26*$C$9,0),"") | I26: =IF(B26="","",IFERROR(INDEX(Catalog!$F$2:$F$70,MATCH(B26,Catalog!$A$2:$A$70,0))&"",""))
A27: =IF(B27="","",ROW()-18) | C27: =IF(B27="","",IFERROR(HYPERLINK(INDEX(Catalog!$B$2:$B$70,MATCH(B27,Catalog!$A$2:$A$70,0)),"Vezi produs"),"")) | E27: =IF(B27="","",IFERROR(INDEX(Catalog!$C$2:$C$70,MATCH(B27,Catalog!$A$2:$A$70,0)),"nu e în listă")) | G27: =IF(AND(ISNUMBER(D27),ISNUMBER(E27)),ROUND(D27*E27*(1-N(F27)),2),"") | H27: =IF(ISNUMBER(G27),ROUND(G27*$C$9,0),"") | I27: =IF(B27="","",IFERROR(INDEX(Catalog!$F$2:$F$70,MATCH(B27,Catalog!$A$2:$A$70,0))&"",""))
A28: =IF(B28="","",ROW()-18) | C28: =IF(B28="","",IFERROR(HYPERLINK(INDEX(Catalog!$B$2:$B$70,MATCH(B28,Catalog!$A$2:$A$70,0)),"Vezi produs"),"")) | E28: =IF(B28="","",IFERROR(INDEX(Catalog!$C$2:$C$70,MATCH(B28,Catalog!$A$2:$A$70,0)),"nu e în listă")) | G28: =IF(AND(ISNUMBER(D28),ISNUMBER(E28)),ROUND(D28*E28*(1-N(F28)),2),"") | H28: =IF(ISNUMBER(G28),ROUND(G28*$C$9,0),"") | I28: =IF(B28="","",IFERROR(INDEX(Catalog!$F$2:$F$70,MATCH(B28,Catalog!$A$2:$A$70,0))&"",""))
E30: Total fără TVA | G30: =SUM(G19:G28) | H30: =SUM(H19:H28)
E31: ="TVA "&TEXT(CotaTVA,"0%") | G31: =ROUND(G30*CotaTVA,2) | H31: =ROUND(H30*CotaTVA,0)
E32: TOTAL cu TVA | G32: =G30+G31 | H32: =H30+H31
A34: CONDIȚII
B35: Garanție: | C35: 12 luni.
B36: Livrare: | C36: Termenul de livrare în funcție de stocul disponibil.
B37: Finanțare: | C37: Asistență și consultanță calificată pentru aplicarea la sisteme de finanțare și subvenționare.
B38: Service: | C38: Asistență tehnică în 48 de ore.
B39: Suport post-vânzare: | C39: Susținem toți clienții printr-o echipă dedicată de piese și accesorii.
B40: Prețuri: | C40: Prețurile sunt în EUR, fără TVA. Suma în MDL este calculată la cursul din C9.
B41: Condiții de plată:
B43: Întocmit de: | E43: Telefon:
B45: Semnătura:
B47: Apăsați aici sau scanați codul pentru site-ul Ozonteh: ozonteh.net

Sheet Instrucțiuni
B2: CUM SE FOLOSEȘTE
B4: OFERTA COMERCIALĂ
B5: 1. Completați câmpurile galbene; după completare devin albe, ca PDF-ul să iasă curat.
B6: 2. În coloana „Produs” apăsați săgeata și alegeți produsul. Prețul (promo, dacă există) și linkul se completează singure din „Lista de prețuri”.
B7: 3. Scrieți cantitatea și, dacă e cazul, reducerea (ex. 5%).
B8: 4. Cursul vine din „Lista de prețuri” (F3); în ofertă îl puteți schimba doar pentru oferta aceasta.
B9: 5. Primul rând e un exemplu: înlocuiți-l sau ștergeți-l.
B11: PDF: DOAR OFERTA
B12: Pe foaia „Ofertă comercială”: Fișier → Descărcare → PDF → Foaia curentă, A4, portret, „Potrivire la lățime”.
B14: PDF: OFERTA + FIȘELE PRODUSELOR ALESE (meniul Ozonteh, doar în Google Sheets)
B15: Meniul „Ozonteh → Descarcă oferta completă (PDF)” face un singur PDF: oferta comercială, apoi oferta (fișa tehnică) fiecărui produs ales, în ordinea din tabel.
B16: PDF-ul se salvează și în Google Drive, în dosarul „Oferte Ozonteh (PDF)”.
... B27: În Google Sheets cursul se poate lega automat: în F3 scrieți =GOOGLEFINANCE("CURRENCY:EURMDL").

Sheet Catalog
A1: Denumire | B1: Link produs | C1: Preț final EUR | D1: Preț listă EUR | E1: Preț promo EUR | F1: Link ofertă | G1: Categorie
A2: ='Lista de prețuri'!C6 | B2: https://ozonteh.net/product/tocator-shaktiman-afm/ | C2: =IF(ISNUMBER('Lista de prețuri'!E6),'Lista de prețuri'!E6,IF(ISNUMBER('Lista de prețuri'!D6),'Lista de prețuri'!D6,"La cerere")) | D2: ='Lista de prețuri'!D6 | E2: =IF(ISNUMBER('Lista de prețuri'!E6),'Lista de prețuri'!E6,"") | F2: https://docs.google.com/spreadsheets/d/1CXkK0ItyxIAIqxW4vkuozfDCTeFBFK2bOTakDbVFslE/edit?usp=sharing | G2: Tocătoare de resturi vegetale
A3: ='Lista de prețuri'!C7 | B3: https://ozonteh.net/product/tocator-shaktiman-afm/ | C3: =IF(ISNUMBER('Lista de prețuri'!E7),'Lista de prețuri'!E7,IF(ISNUMBER('Lista de prețuri'!D7),'Lista de prețuri'!D7,"La cerere")) | D3: ='Lista de prețuri'!D7 | E3: =IF(ISNUMBER('Lista de prețuri'!E7),'Lista de prețuri'!E7,"") | F3: https://docs.google.com/spreadsheets/d/11Qv4P7lFPcEDoh3VjBqzTBHIHMJPLFnAoZX1w4akAuE/edit?usp=sharing | G3: Tocătoare de resturi vegetale
A4: ='Lista de prețuri'!C8 | B4: https://ozonteh.net/product/tocator-shaktiman-bmf/ | C4: =IF(ISNUMBER('Lista de prețuri'!E8),'Lista de prețuri'!E8,IF(ISNUMBER('Lista de prețuri'!D8),'Lista de prețuri'!D8,"La cerere")) | D4: ='Lista de prețuri'!D8 | E4: =IF(ISNUMBER('Lista de prețuri'!E8),'Lista de prețuri'!E8,"") | F4: https://docs.google.com/spreadsheets/d/17ajncHgjQHD4XVyM3_jr7RA9FlROw4kCJNlOpmbo9d8/edit?usp=sharing | G4: Tocătoare de resturi vegetale
A5: ='Lista de prețuri'!C9 | B5: https://ozonteh.net/product/tocator-shaktiman-bmf/ | C5: =IF(ISNUMBER('Lista de prețuri'!E9),'Lista de prețuri'!E9,IF(ISNUMBER('Lista de prețuri'!D9),'Lista de prețuri'!D9,"La cerere")) | D5: ='Lista de prețuri'!D9 | E5: =IF(ISNUMBER('Lista de prețuri'!E9),'Lista de prețuri'!E9,"") | F5: https://docs.google.com/spreadsheets/d/1r6RMANLjYb7QK4w9wJQRI_A29-G0snlwcwQ25qslw9k/edit?usp=sharing | G5: Tocătoare de resturi vegetale
A6: ='Lista de prețuri'!C10 | B6: https://ozonteh.net/product/tocator-shaktiman-bmf/ | C6: =IF(ISNUMBER('Lista de prețuri'!E10),'Lista de prețuri'!E10,IF(ISNUMBER('Lista de prețuri'!D10),'Lista de prețuri'!D10,"La cerere")) | D6: ='Lista de prețuri'!D10 | E6: =IF(ISNUMBER('Lista de prețuri'!E10),'Lista de prețuri'!E10,"") | F6: https://docs.google.com/spreadsheets/d/1HfLhZKBpEZDAqOhNj77nIUSbBlG5AWRsJnTOdow9N0o/edit?usp=sharing | G6: Tocătoare de resturi vegetale
A7: ='Lista de prețuri'!C11 | B7: https://ozonteh.net/product/tocator-shaktiman-bmf/ | C7: =IF(ISNUMBER('Lista de prețuri'!E11),'Lista de prețuri'!E11,IF(ISNUMBER('Lista de prețuri'!D11),'Lista de prețuri'!D11,"La cerere")) | D7: ='Lista de prețuri'!D11 | E7: =IF(ISNUMBER('Lista de prețuri'!E11),'Lista de prețuri'!E11,"") | F7: https://docs.google.com/spreadsheets/d/1NUuMEYaakNKEAQNzkhGg_hpi15iCu2ucLLI16-K7BE0/edit?usp=sharing | G7: Tocătoare de resturi vegetale
A8: ='Lista de prețuri'!C12 | B8: https://ozonteh.net/product/tocator-shaktiman-bmf/ | C8: =IF(ISNUMBER('Lista de prețuri'!E12),'Lista de prețuri'!E12,IF(ISNUMBER('Lista de prețuri'!D12),'Lista de prețuri'!D12,"La cerere")) | D8: ='Lista de prețuri'!D12 | E8: =IF(ISNUMBER('Lista de prețuri'!E12),'Lista de prețuri'!E12,"") | F8: https://docs.google.com/spreadsheets/d/1lS9OA4xc6Zh0IheX8orc_RNht2rLft-6r5zBzSxUM98/edit?usp=sharing | G8: Tocătoare de resturi vegetale
A9: ='Lista de prețuri'!C13 | B9: https://ozonteh.net/product/tocator-shaktiman-bpf/ | C9: =IF(ISNUMBER('Lista de prețuri'!E13),'Lista de prețuri'!E13,IF(ISNUMBER('Lista de prețuri'!D13),'Lista de prețuri'!D13,"La cerere")) | D9: ='Lista de prețuri'!D13 | E9: =IF(ISNUMBER('Lista de prețuri'!E13),'Lista de prețuri'!E13,"") | F9: https://docs.google.com/spreadsheets/d/1j0T44xCNkUDuWfbBeC_nQOtFtEL88StZkmoF9DRNmHg/edit?usp=sharing | G9: Tocătoare de resturi vegetale
A10: ='Lista de prețuri'!C14 | B10: https://ozonteh.net/product/tocator-shaktiman-bpf/ | C10: =IF(ISNUMBER('Lista de prețuri'!E14),'Lista de prețuri'!E14,IF(ISNUMBER('Lista de prețuri'!D14),'Lista de prețuri'!D14,"La cerere")) | D10: ='Lista de prețuri'!D14 | E10: =IF(ISNUMBER('Lista de prețuri'!E14),'Lista de prețuri'!E14,"") | F10: https://docs.google.com/spreadsheets/d/1OYQ0AbKni0w8bQGkwfN4UJz2siUJgyWzHztgB0f47vc/edit?usp=sharing | G10: Tocătoare de resturi vegetale
A11: ='Lista de prețuri'!C15 | B11: https://ozonteh.net/product/tocator-shaktiman-bpf/ | C11: =IF(ISNUMBER('Lista de prețuri'!E15),'Lista de prețuri'!E15,IF(ISNUMBER('Lista de prețuri'!D15),'Lista de prețuri'!D15,"La cerere")) | D11: ='Lista de prețuri'!D15 | E11: =IF(ISNUMBER('Lista de prețuri'!E15),'Lista de prețuri'!E15,"") | F11: https://docs.google.com/spreadsheets/d/1OEogHx_IYuzv0ewoJ2m2tUd_8ijyM0BZUdkRAfS8MCs/edit?usp=sharing | G11: Tocătoare de resturi vegetale
A12: ='Lista de prețuri'!C16 | B12: https://ozonteh.net/product/tocator-shaktiman-bpf/ | C12: =IF(ISNUMBER('Lista de prețuri'!E16),'Lista de prețuri'!E16,IF(ISNUMBER('Lista de prețuri'!D16),'Lista de prețuri'!D16,"La cerere")) | D12: ='Lista de prețuri'!D16 | E12: =IF(ISNUMBER('Lista de prețuri'!E16),'Lista de prețuri'!E16,"") | G12: Tocătoare de resturi vegetale
A13: ='Lista de prețuri'!C17 | B13: https://ozonteh.net/product/tocator-shaktiman-spfm/ | C13: =IF(ISNUMBER('Lista de prețuri'!E17),'Lista de prețuri'!E17,IF(ISNUMBER('Lista de prețuri'!D17),'Lista de prețuri'!D17,"La cerere")) | D13: ='Lista de prețuri'!D17 | E13: =IF(ISNUMBER('Lista de prețuri'!E17),'Lista de prețuri'!E17,"") | F13: https://docs.google.com/spreadsheets/d/1ObP7sga55mHSHB9fLh3tL4mkVqAn5ZzQimK9ajEQ4cA/edit?gid=1922752811 | G13: Tocătoare de resturi vegetale
A14: ='Lista de prețuri'!C18 | B14: https://ozonteh.net/product/tocator-shaktiman-spfm/ | C14: =IF(ISNUMBER('Lista de prețuri'!E18),'Lista de prețuri'!E18,IF(ISNUMBER('Lista de prețuri'!D18),'Lista de prețuri'!D18,"La cerere")) | D14: ='Lista de prețuri'!D18 | E14: =IF(ISNUMBER('Lista de prețuri'!E18),'Lista de prețuri'!E18,"") | F14: https://docs.google.com/spreadsheets/d/1lXIXyzeUyNviWraEwntyAZNCKRxVi95QuLhXBtzfCr4/edit?usp=sharing | G14: Tocătoare de resturi vegetale
A15: ='Lista de prețuri'!C19 | B15: https://ozonteh.net/product/tocator-cu-descarcare-laterala-shaktiman-sdfm/ | C15: =IF(ISNUMBER('Lista de prețuri'!E19),'Lista de prețuri'!E19,IF(ISNUMBER('Lista de prețuri'!D19),'Lista de prețuri'!D19,"La cerere")) | D15: ='Lista de prețuri'!D19 | E15: =IF(ISNUMBER('Lista de prețuri'!E19),'Lista de prețuri'!E19,"") | F15: https://docs.google.com/spreadsheets/d/1MJYYY_GfTiUlLcixDgdnHL3Kem1oUypUUFxH2AmwfyY/edit?usp=sharing | G15: Tocătoare de resturi vegetale
A16: ='Lista de prețuri'!C20 | B16: https://ozonteh.net/product/tocator-shaktiman-bma/ | C16: =IF(ISNUMBER('Lista de prețuri'!E20),'Lista de prețuri'!E20,IF(ISNUMBER('Lista de prețuri'!D20),'Lista de prețuri'!D20,"La cerere")) | D16: ='Lista de prețuri'!D20 | E16: =IF(ISNUMBER('Lista de prețuri'!E20),'Lista de prețuri'!E20,"") | F16: https://docs.google.com/spreadsheets/d/1kC780ekUbYbcJmTq2gp4C_CP_pVxqaB8OUzN2SwPUoU/edit?usp=sharing | G16: Tocătoare de resturi vegetale
A17: ='Lista de prețuri'!C21 | B17: https://ozonteh.net/product/tocator-shaktiman-bma/ | C17: =IF(ISNUMBER('Lista de prețuri'!E21),'Lista de prețuri'!E21,IF(ISNUMBER('Lista de prețuri'!D21),'Lista de prețuri'!D21,"La cerere")) | D17: ='Lista de prețuri'!D21 | E17: =IF(ISNUMBER('Lista de prețuri'!E21),'Lista de prețuri'!E21,"") | F17: https://docs.google.com/spreadsheets/d/1dMtlN5kWLg93ZsZjtzVdV-tvZrZcjJQeYgD4ei0Rhmw/edit?usp=sharing | G17: Tocătoare de resturi vegetale
A18: ='Lista de prețuri'!C22 | B18: https://ozonteh.net/product/tocator-shaktiman-sfm-ul/ | C18: =IF(ISNUMBER('Lista de prețuri'!E22),'Lista de prețuri'!E22,IF(ISNUMBER('Lista de prețuri'!D22),'Lista de prețuri'!D22,"La cerere")) | D18: ='Lista de prețuri'!D22 | E18: =IF(ISNUMBER('Lista de prețuri'!E22),'Lista de prețuri'!E22,"") | G18: Tocătoare de resturi vegetale
A19: ='Lista de prețuri'!C23 | B19: https://ozonteh.net/product/tocator-shaktiman-sfm-ul/ | C19: =IF(ISNUMBER('Lista de prețuri'!E23),'Lista de prețuri'!E23,IF(ISNUMBER('Lista de prețuri'!D23),'Lista de prețuri'!D23,"La cerere")) | D19: ='Lista de prețuri'!D23 | E19: =IF(ISNUMBER('Lista de prețuri'!E23),'Lista de prețuri'!E23,"") | G19: Tocătoare de resturi vegetale
A20: ='Lista de prețuri'!C24 | B20: https://ozonteh.net/product/tocator-shaktiman-sfm-ul/ | C20: =IF(ISNUMBER('Lista de prețuri'!E24),'Lista de prețuri'!E24,IF(ISNUMBER('Lista de prețuri'!D24),'Lista de prețuri'!D24,"La cerere")) | D20: ='Lista de prețuri'!D24 | E20: =IF(ISNUMBER('Lista de prețuri'!E24),'Lista de prețuri'!E24,"") | F20: https://docs.google.com/spreadsheets/d/1Cl2P7BxvJAuJIAgocJ4ZIBDSu4r6fjLIOsV__4VSKcM/edit?usp=sharing | G20: Tocătoare de resturi vegetale
A21: ='Lista de prețuri'!C25 | B21: https://ozonteh.net/product/tocator-shaktiman-sfm-ul/ | C21: =IF(ISNUMBER('Lista de prețuri'!E25),'Lista de prețuri'!E25,IF(ISNUMBER('Lista de prețuri'!D25),'Lista de prețuri'!D25,"La cerere")) | D21: ='Lista de prețuri'!D25 | E21: =IF(ISNUMBER('Lista de prețuri'!E25),'Lista de prețuri'!E25,"") | F21: https://docs.google.com/spreadsheets/d/1zc4yF3Yp9qvsrRD4W3fWbGVEvaZ1P1mECVGdAmwRwnw/edit?usp=sharing | G21: Tocătoare de resturi vegetale
A22: ='Lista de prețuri'!C26 | B22: https://ozonteh.net/product/tocator-shaktiman-sfm-ul/ | C22: =IF(ISNUMBER('Lista de prețuri'!E26),'Lista de prețuri'!E26,IF(ISNUMBER('Lista de prețuri'!D26),'Lista de prețuri'!D26,"La cerere")) | D22: ='Lista de prețuri'!D26 | E22: =IF(ISNUMBER('Lista de prețuri'!E26),'Lista de prețuri'!E26,"") | F22: https://docs.google.com/spreadsheets/d/1C4Xx9-j4LOekK_ZmX9MjKMHOT6M_8jyRrEiRTGO2Ea4/edit?usp=sharing | G22: Tocătoare de resturi vegetale
A23: ='Lista de prețuri'!C27 | B23: https://ozonteh.net/product/tocator-shaktiman-sfm/ | C23: =IF(ISNUMBER('Lista de prețuri'!E27),'Lista de prețuri'!E27,IF(ISNUMBER('Lista de prețuri'!D27),'Lista de prețuri'!D27,"La cerere")) | D23: ='Lista de prețuri'!D27 | E23: =IF(ISNUMBER('Lista de prețuri'!E27),'Lista de prețuri'!E27,"") | F23: https://docs.google.com/spreadsheets/d/1tgDcbe7uHwcGY1fryPt9MJ_2f4x9-UGZAzq8Yr_KKZY/edit?usp=sharing | G23: Tocătoare de resturi vegetale
A24: ='Lista de prețuri'!C28 | B24: https://ozonteh.net/product/tocator-shaktiman-sfm/ | C24: =IF(ISNUMBER('Lista de prețuri'!E28),'Lista de prețuri'!E28,IF(ISNUMBER('Lista de prețuri'!D28),'Lista de prețuri'!D28,"La cerere")) | D24: ='Lista de prețuri'!D28 | E24: =IF(ISNUMBER('Lista de prețuri'!E28),'Lista de prețuri'!E28,"") | F24: https://docs.google.com/spreadsheets/d/1FZIBfqwUpDxsbK551gVAVhTkrScbhK5tHD_i9XaSTig/edit?usp=sharing | G24: Tocătoare de resturi vegetale
A25: ='Lista de prețuri'!C29 | B25: https://ozonteh.net/product/tocator-shaktiman-sfm/ | C25: =IF(ISNUMBER('Lista de prețuri'!E29),'Lista de prețuri'!E29,IF(ISNUMBER('Lista de prețuri'!D29),'Lista de prețuri'!D29,"La cerere")) | D25: ='Lista de prețuri'!D29 | E25: =IF(ISNUMBER('Lista de prețuri'!E29),'Lista de prețuri'!E29,"") | F25: https://docs.google.com/spreadsheets/d/1zCNDDCzqneudjD48TX0PPZW1SunMh8NEn68UViIdBco/edit?usp=sharing | G25: Tocătoare de resturi vegetale
A26: ='Lista de prețuri'!C30 | B26: https://ozonteh.net/product/tocator-shaktiman-sfm/ | C26: =IF(ISNUMBER('Lista de prețuri'!E30),'Lista de prețuri'!E30,IF(ISNUMBER('Lista de prețuri'!D30),'Lista de prețuri'!D30,"La cerere")) | D26: ='Lista de prețuri'!D30 | E26: =IF(ISNUMBER('Lista de prețuri'!E30),'Lista de prețuri'!E30,"") | F26: https://docs.google.com/spreadsheets/d/1wGRmMnrxPvmyiQDXqQxFLwqyUj206spYFEkuedS58dA/edit?usp=sharing | G26: Tocătoare de resturi vegetale
A27: ='Lista de prețuri'!C31 | B27: https://ozonteh.net/product/tocator-shaktiman-sfm/ | C27: =IF(ISNUMBER('Lista de prețuri'!E31),'Lista de prețuri'!E31,IF(ISNUMBER('Lista de prețuri'!D31),'Lista de prețuri'!D31,"La cerere")) | D27: ='Lista de prețuri'!D31 | E27: =IF(ISNUMBER('Lista de prețuri'!E31),'Lista de prețuri'!E31,"") | F27: https://docs.google.com/spreadsheets/d/1_sOXq3HsNLLJhHysigo3Titq-BB4RG8oSlcXT9D7DOE/edit?usp=sharing | G27: Tocătoare de resturi vegetale
A28: ='Lista de prețuri'!C32 | B28: https://ozonteh.net/product/tocator-de-resturi-vegetale-si-a-furajelor-verzi-shaktiman-12-sm/ | C28: =IF(ISNUMBER('Lista de prețuri'!E32),'Lista de prețuri'!E32,IF(ISNUMBER('Lista de prețuri'!D32),'Lista de prețuri'!D32,"La cerere")) | D28: ='Lista de prețuri'!D32 | E28: =IF(ISNUMBER('Lista de prețuri'!E32),'Lista de prețuri'!E32,"") | F28: https://docs.google.com/spreadsheets/d/1JrzI31fr-fR8gKLQwP_eZ2x0aJBSjj1xRAuHiscilg4/edit?usp=sharing | G28: Tocătoare de resturi vegetale
A29: ='Lista de prețuri'!C34 | B29: https://ozonteh.net/product/freza-de-sol-shaktiman-mini-plus/ | C29: =IF(ISNUMBER('Lista de prețuri'!E34),'Lista de prețuri'!E34,IF(ISNUMBER('Lista de prețuri'!D34),'Lista de prețuri'!D34,"La cerere")) | D29: ='Lista de prețuri'!D34 | E29: =IF(ISNUMBER('Lista de prețuri'!E34),'Lista de prețuri'!E34,"") | F29: https://docs.google.com/spreadsheets/d/18p2w-aADJq2_HKxNxfKozPM41kH_DVWl2VzP7BXl8fo/edit?usp=sharing | G29: Freze de sol
A30: ='Lista de prețuri'!C35 | B30: https://ozonteh.net/product/freza-de-sol-shaktiman-mini-plus/ | C30: =IF(ISNUMBER('Lista de prețuri'!E35),'Lista de prețuri'!E35,IF(ISNUMBER('Lista de prețuri'!D35),'Lista de prețuri'!D35,"La cerere")) | D30: ='Lista de prețuri'!D35 | E30: =IF(ISNUMBER('Lista de prețuri'!E35),'Lista de prețuri'!E35,"") | F30: https://docs.google.com/spreadsheets/d/1PsbxoeDJj-eMJH8RJBum3G7Z-HgeI5aH1xcGPAQIQko/edit?usp=sharing | G30: Freze de sol
A31: ='Lista de prețuri'!C36 | B31: https://ozonteh.net/product/freza-de-sol-shaktiman-ul/ | C31: =IF(ISNUMBER('Lista de prețuri'!E36),'Lista de prețuri'!E36,IF(ISNUMBER('Lista de prețuri'!D36),'Lista de prețuri'!D36,"La cerere")) | D31: ='Lista de prețuri'!D36 | E31: =IF(ISNUMBER('Lista de prețuri'!E36),'Lista de prețuri'!E36,"") | F31: https://docs.google.com/spreadsheets/d/1MvHq7JQ3vsiJxzhCJiN4R_bX1grcgnJZKBVNbewO1VU/edit?usp=sharing | G31: Freze de sol
A32: ='Lista de prețuri'!C37 | B32: https://ozonteh.net/product/freza-de-sol-shaktiman-ul/ | C32: =IF(ISNUMBER('Lista de prețuri'!E37),'Lista de prețuri'!E37,IF(ISNUMBER('Lista de prețuri'!D37),'Lista de prețuri'!D37,"La cerere")) | D32: ='Lista de prețuri'!D37 | E32: =IF(ISNUMBER('Lista de prețuri'!E37),'Lista de prețuri'!E37,"") | F32: https://docs.google.com/spreadsheets/d/1fcmIXEdl9ZcgQKKcxEf33TauSZ430dyd8UYnOJ9FCeo/edit?usp=sharing | G32: Freze de sol
A33: ='Lista de prețuri'!C38 | B33: https://ozonteh.net/product/freza-de-sol-shaktiman-um/ | C33: =IF(ISNUMBER('Lista de prețuri'!E38),'Lista de prețuri'!E38,IF(ISNUMBER('Lista de prețuri'!D38),'Lista de prețuri'!D38,"La cerere")) | D33: ='Lista de prețuri'!D38 | E33: =IF(ISNUMBER('Lista de prețuri'!E38),'Lista de prețuri'!E38,"") | F33: https://docs.google.com/spreadsheets/d/1LkGFEfUtpzKxAJKVfjyS6iGAX2QkopArDLkQfuNV4qg/edit?usp=sharing | G33: Freze de sol
A34: ='Lista de prețuri'!C39 | B34: https://ozonteh.net/product/freza-de-sol-shaktiman-um/ | C34: =IF(ISNUMBER('Lista de prețuri'!E39),'Lista de prețuri'!E39,IF(ISNUMBER('Lista de prețuri'!D39),'Lista de prețuri'!D39,"La cerere")) | D34: ='Lista de prețuri'!D39 | E34: =IF(ISNUMBER('Lista de prețuri'!E39),'Lista de prețuri'!E39,"") | F34: https://docs.google.com/spreadsheets/d/1QCnK48znWFg3TtdqYZwCjLDmmYpf3lSM1PKyduq2tGE/edit?usp=sharing | G34: Freze de sol
A35: ='Lista de prețuri'!C40 | B35: https://ozonteh.net/product/freza-de-sol-shaktiman-um/ | C35: =IF(ISNUMBER('Lista de prețuri'!E40),'Lista de prețuri'!E40,IF(ISNUMBER('Lista de prețuri'!D40),'Lista de prețuri'!D40,"La cerere")) | D35: ='Lista de prețuri'!D40 | E35: =IF(ISNUMBER('Lista de prețuri'!E40),'Lista de prețuri'!E40,"") | F35: https://docs.google.com/spreadsheets/d/1l3CDErMmCUHYQVfYKsbEK8ua-k4TB3UwETx4wgZPudA/edit?usp=sharing | G35: Freze de sol
A36: ='Lista de prețuri'!C41 | B36: https://ozonteh.net/product/freza-de-sol-shaktiman-um/ | C36: =IF(ISNUMBER('Lista de prețuri'!E41),'Lista de prețuri'!E41,IF(ISNUMBER('Lista de prețuri'!D41),'Lista de prețuri'!D41,"La cerere")) | D36: ='Lista de prețuri'!D41 | E36: =IF(ISNUMBER('Lista de prețuri'!E41),'Lista de prețuri'!E41,"") | F36: https://docs.google.com/spreadsheets/d/1zfFvezNR7CRaf-Hd57HIvGIZP91Tbpurhf-wDThvaUA/edit?usp=sharing | G36: Freze de sol
A37: ='Lista de prețuri'!C42 | B37: https://ozonteh.net/product/freza-de-sol-shaktiman-semi-champion/ | C37: =IF(ISNUMBER('Lista de prețuri'!E42),'Lista de prețuri'!E42,IF(ISNUMBER('Lista de prețuri'!D42),'Lista de prețuri'!D42,"La cerere")) | D37: ='Lista de prețuri'!D42 | E37: =IF(ISNUMBER('Lista de prețuri'!E42),'Lista de prețuri'!E42,"") | F37: https://docs.google.com/spreadsheets/d/1Is8Cy2WwcVNY4QULJzPAnwysklFUSGRTPshoisdIsA0/edit?usp=sharing | G37: Freze de sol
A38: ='Lista de prețuri'!C43 | B38: https://ozonteh.net/product/freza-de-sol-shaktiman-semi-champion/ | C38: =IF(ISNUMBER('Lista de prețuri'!E43),'Lista de prețuri'!E43,IF(ISNUMBER('Lista de prețuri'!D43),'Lista de prețuri'!D43,"La cerere")) | D38: ='Lista de prețuri'!D43 | E38: =IF(ISNUMBER('Lista de prețuri'!E43),'Lista de prețuri'!E43,"") | F38: https://docs.google.com/spreadsheets/d/1TceIzq9myJogWO--x-IfN2BDHilX-ju6_nbN57ifby4/edit?usp=sharing | G38: Freze de sol
A39: ='Lista de prețuri'!C44 | B39: https://ozonteh.net/product/freza-de-sol-shaktiman-semi-champion/ | C39: =IF(ISNUMBER('Lista de prețuri'!E44),'Lista de prețuri'!E44,IF(ISNUMBER('Lista de prețuri'!D44),'Lista de prețuri'!D44,"La cerere")) | D39: ='Lista de prețuri'!D44 | E39: =IF(ISNUMBER('Lista de prețuri'!E44),'Lista de prețuri'!E44,"") | F39: https://docs.google.com/spreadsheets/d/15URF8uzXPuHHu9B8eAQhT_91JHjp6JlBee2j74HZjtE/edit?usp=sharing | G39: Freze de sol
A40: ='Lista de prețuri'!C45 | B40: https://ozonteh.net/product/freza-de-sol-shaktiman-semi-champion/ | C40: =IF(ISNUMBER('Lista de prețuri'!E45),'Lista de prețuri'!E45,IF(ISNUMBER('Lista de prețuri'!D45),'Lista de prețuri'!D45,"La cerere")) | D40: ='Lista de prețuri'!D45 | E40: =IF(ISNUMBER('Lista de prețuri'!E45),'Lista de prețuri'!E45,"") | F40: https://docs.google.com/spreadsheets/d/1QdQU8IxLFMGVqUIob0GmMy0ey9I3f-5T52tHV6kEJyQ/edit?usp=sharing | G40: Freze de sol
...
