Workbook
Name Curs: 'Lista de prețuri'!$F$3
Name CotaTVA: 'Ofertă comercială'!$F$9

Sheet Lista de prețuri
C1: LISTA DE PREȚURI
C2: Tractoare LS, Farmtrac, Antonio Carraro și Solis
C3: Prețuri în EUR, fără TVA | E3: Curs EUR/MDL: | F3: 20.1 | G3: Actualizat: | H3: 46308
C4: „Ozonteh Impex” SRL · MD-3701, mun. Strășeni, șos. Chișinău 69, Republica Moldova · office@ozonteh.md · ozonteh.net
A6: Nr. | B6: Foto | C6: Denumire produs | D6: Preț EUR (fără TVA) | E6: Preț promo EUR | F6: Preț MDL* (fără TVA) | G6: Notă | H6: Pagina produsului | I6: Ofertă comercială
A7: TRACTOARE LS · 14 modele
A8: 1 | C8: Tractor LS MT1.25 HST FR STAGE V | D8: 12500 | F8: =IF(ISNUMBER(E8),ROUND(E8*Curs,0),IF(ISNUMBER(D8),ROUND(D8*Curs,0),"La cerere")) | H8: Vezi pe site | I8: Deschide oferta
A9: 2 | C9: Tractor LS XJ25 MT FR STAGE V | D9: 12500 | F9: =IF(ISNUMBER(E9),ROUND(E9*Curs,0),IF(ISNUMBER(D9),ROUND(D9*Curs,0),"La cerere")) | H9: Vezi pe site | I9: Deschide oferta
A10: 3 | C10: Tractor LS MT3.40 MT CAB STAGE V | D10: 25000 | F10: =IF(ISNUMBER(E10),ROUND(E10*Curs,0),IF(ISNUMBER(D10),ROUND(D10*Curs,0),"La cerere")) | H10: Vezi pe site | I10: Deschide oferta
A11: 4 | C11: Tractor LS MT3.50 MT CAB STAGE V | D11: 28000 | F11: =IF(ISNUMBER(E11),ROUND(E11*Curs,0),IF(ISNUMBER(D11),ROUND(D11*Curs,0),"La cerere")) | H11: Vezi pe site | I11: Deschide oferta
A12: 5 | C12: Tractor LS MT3.60 MT CAB STAGE V | D12: 30000 | F12: =IF(ISNUMBER(E12),ROUND(E12*Curs,0),IF(ISNUMBER(D12),ROUND(D12*Curs,0),"La cerere")) | H12: Vezi pe site | I12: Deschide oferta
A13: 6 | C13: Tractor LS R36i MT FR NON EU | D13: 16500 | F13: =IF(ISNUMBER(E13),ROUND(E13*Curs,0),IF(ISNUMBER(D13),ROUND(D13*Curs,0),"La cerere")) | H13: Vezi pe site | I13: Deschide oferta
A14: 7 | C14: Tractor LS R60 MT FR NON EU | D14: 21000 | E14: 19500 | F14: =IF(ISNUMBER(E14),ROUND(E14*Curs,0),IF(ISNUMBER(D14),ROUND(D14*Curs,0),"La cerere")) | H14: Vezi pe site | I14: Deschide oferta
A15: 8 | C15: Tractor LS R65 MT CAB NON EU | D15: 29000 | E15: 27500 | F15: =IF(ISNUMBER(E15),ROUND(E15*Curs,0),IF(ISNUMBER(D15),ROUND(D15*Curs,0),"La cerere")) | H15: Vezi pe site | I15: Deschide oferta
A16: 9 | C16: Tractor LS XR50 MT CAB NON EU | D16: 26000 | E16: 25000 | F16: =IF(ISNUMBER(E16),ROUND(E16*Curs,0),IF(ISNUMBER(D16),ROUND(D16*Curs,0),"La cerere")) | H16: Vezi pe site | I16: Deschide oferta
A17: 10 | C17: Tractor LS U60 MT CAB NON EU | D17: 29500 | E17: 28000 | F17: =IF(ISNUMBER(E17),ROUND(E17*Curs,0),IF(ISNUMBER(D17),ROUND(D17*Curs,0),"La cerere")) | H17: Vezi pe site | I17: Deschide oferta
A18: 11 | C18: Tractor LS XU6168 MT CAB STAGE V | D18: 33000 | F18: =IF(ISNUMBER(E18),ROUND(E18*Curs,0),IF(ISNUMBER(D18),ROUND(D18*Curs,0),"La cerere")) | H18: Vezi pe site | I18: Deschide oferta
A19: 12 | C19: Tractor LS MT5.73 PS CAB STAGE V | D19: 41000 | F19: =IF(ISNUMBER(E19),ROUND(E19*Curs,0),IF(ISNUMBER(D19),ROUND(D19*Curs,0),"La cerere")) | H19: Vezi pe site | I19: Deschide oferta
A20: 13 | C20: Tractor LS PLUS100 PS CAB NON EU | D20: 43000 | E20: 41000 | F20: =IF(ISNUMBER(E20),ROUND(E20*Curs,0),IF(ISNUMBER(D20),ROUND(D20*Curs,0),"La cerere")) | H20: Vezi pe site | I20: Deschide oferta
A21: 14 | C21: Tractor LS MT7.101 PS CAB STAGE V | D21: 53000 | F21: =IF(ISNUMBER(E21),ROUND(E21*Curs,0),IF(ISNUMBER(D21),ROUND(D21*Curs,0),"La cerere")) | H21: Vezi pe site | I21: Deschide oferta
A22: TRACTOARE FARMTRAC · 8 modele
A23: 15 | C23: Set tractor Farmtrac 26 + freză Shaktiman | D23: 9900 | E23: 9000 | F23: =IF(ISNUMBER(E23),ROUND(E23*Curs,0),IF(ISNUMBER(D23),ROUND(D23*Curs,0),"La cerere")) | G23: Ofertă de iarnă | H23: Vezi pe site | I23: Deschide oferta
A24: 16 | C24: Tractor Farmtrac 26 4WD | D24: 8500 | E24: 8000 | F24: =IF(ISNUMBER(E24),ROUND(E24*Curs,0),IF(ISNUMBER(D24),ROUND(D24*Curs,0),"La cerere")) | H24: Vezi pe site | I24: Deschide oferta
A25: 17 | C25: Tractor Farmtrac 26 Pro 4WD | D25: 8500 | F25: =IF(ISNUMBER(E25),ROUND(E25*Curs,0),IF(ISNUMBER(D25),ROUND(D25*Curs,0),"La cerere")) | G25: Model nou, Stage 5, 9x9 | H25: Vezi pe site | I25: Deschide oferta
A26: 18 | C26: Tractor Farmtrac 30 4WD | D26: 9000 | F26: =IF(ISNUMBER(E26),ROUND(E26*Curs,0),IF(ISNUMBER(D26),ROUND(D26*Curs,0),"La cerere")) | H26: Vezi pe site | I26: Deschide oferta
A27: 19 | C27: Tractor Farmtrac 35 4WD | D27: 9500 | F27: =IF(ISNUMBER(E27),ROUND(E27*Curs,0),IF(ISNUMBER(D27),ROUND(D27*Curs,0),"La cerere")) | H27: Vezi pe site | I27: Deschide oferta
A28: 20 | C28: Tractor Farmtrac 35 4WD Revers | D28: 9800 | F28: =IF(ISNUMBER(E28),ROUND(E28*Curs,0),IF(ISNUMBER(D28),ROUND(D28*Curs,0),"La cerere")) | H28: Vezi pe site | I28: Deschide oferta
A29: 21 | C29: Tractor Farmtrac 6075N 4WD | D29: 19500 | E29: 16999 | F29: =IF(ISNUMBER(E29),ROUND(E29*Curs,0),IF(ISNUMBER(D29),ROUND(D29*Curs,0),"La cerere")) | H29: Vezi pe site | I29: Deschide oferta
A30: 22 | C30: Tractor Farmtrac 6075N 4WD Cabină | D30: 24500 | E30: 23000 | F30: =IF(ISNUMBER(E30),ROUND(E30*Curs,0),IF(ISNUMBER(D30),ROUND(D30*Curs,0),"La cerere")) | H30: Vezi pe site | I30: Deschide oferta
A31: TRACTOARE ANTONIO CARRARO · 3 modele
A32: 23 | C32: Tractor Antonio Carraro AV2100L | D32: 48000 | F32: =IF(ISNUMBER(E32),ROUND(E32*Curs,0),IF(ISNUMBER(D32),ROUND(D32*Curs,0),"La cerere")) | H32: — | I32: Deschide oferta
A33: 24 | C33: Tractor Antonio Carraro TGF 9900 | D33: 45000 | F33: =IF(ISNUMBER(E33),ROUND(E33*Curs,0),IF(ISNUMBER(D33),ROUND(D33*Curs,0),"La cerere")) | H33: — | I33: Deschide oferta
A34: 25 | C34: Tractor Antonio Carraro TRG 9900 | D34: 48000 | F34: =IF(ISNUMBER(E34),ROUND(E34*Curs,0),IF(ISNUMBER(D34),ROUND(D34*Curs,0),"La cerere")) | G34: Reversibil | H34: Vezi pe site | I34: Deschide oferta
A35: TRACTOARE SOLIS · 8 modele
A36: 26 | C36: Tractor Solis S16 | D36: 6000 | F36: =IF(ISNUMBER(E36),ROUND(E36*Curs,0),IF(ISNUMBER(D36),ROUND(D36*Curs,0),"La cerere")) | H36: Vezi pe site | I36: Deschide oferta
A37: 27 | C37: Tractor Solis S26 | D37: 8000 | F37: =IF(ISNUMBER(E37),ROUND(E37*Curs,0),IF(ISNUMBER(D37),ROUND(D37*Curs,0),"La cerere")) | H37: Vezi pe site | I37: Deschide oferta
A38: 28 | C38: Tractor Solis S26 Xtra | D38: 8300 | F38: =IF(ISNUMBER(E38),ROUND(E38*Curs,0),IF(ISNUMBER(D38),ROUND(D38*Curs,0),"La cerere")) | H38: Vezi pe site | I38: Deschide oferta
A39: 29 | C39: Tractor Solis S26 Shuttle XL | D39: 8500 | F39: =IF(ISNUMBER(E39),ROUND(E39*Curs,0),IF(ISNUMBER(D39),ROUND(D39*Curs,0),"La cerere")) | H39: Vezi pe site | I39: Deschide oferta
A40: 30 | C40: Tractor Solis S30 | D40: 8700 | F40: =IF(ISNUMBER(E40),ROUND(E40*Curs,0),IF(ISNUMBER(D40),ROUND(D40*Curs,0),"La cerere")) | H40: Vezi pe site | I40: Deschide oferta
A41: 31 | C41: Tractor Solis S32 | D41: 9100 | F41: =IF(ISNUMBER(E41),ROUND(E41*Curs,0),IF(ISNUMBER(D41),ROUND(D41*Curs,0),"La cerere")) | H41: Vezi pe site | I41: Deschide oferta
...

Sheet Ofertă comercială
D1: „Ozonteh Impex” SRL
D2: MD-3701, mun. Strășeni, șos. Chișinău 69, Republica Moldova
D3: C.F. 1013600012644 · Cod TVA 8600854
D4: office@ozonteh.md · ozonteh.net
A7: OFERTĂ COMERCIALĂ
B8: Nr. ofertei: | E8: Data: | G8: Valabilă (zile): | H8: 14 | J8: CUM SE FOLOSEȘTE (coloana aceasta nu se tipărește)
B9: Curs EUR/MDL: | C9: =Curs | E9: Cota TVA: | F9: 0.2 | G9: Valabilă până la: | H9: =IF(ISNUMBER(F8),F8+H8,"") | J9: 1. Completați câmpurile galbene; după completare devin albe.
J10: 2. În coloana „Produs” apăsați săgeata și alegeți produsul.
A11: DATE CLIENT | J11: Prețul și linkul la produs se completează singure din „Lista de prețuri”.
B12: Client / companie: | J12: 3. Scrieți cantitatea și, dacă e cazul, reducerea (ex. 5%).
B13: Persoană de contact: | J13: 4. Cursul vine din „Lista de prețuri” (F3); îl puteți schimba aici, doar pentru oferta aceasta.
B14: Telefon: | E14: E-mail: | J14: 5. Primul rând e un exemplu: înlocuiți-l sau ștergeți-l.
B15: Localitate / adresă: | J15: 6. Pentru PDF: Fișier → Descărcare → PDF (o pagină, portret).
A17: PRODUSE OFERITE
A18: Nr. | B18: Produs (alegeți din listă) | C18: Pagina produsului | D18: Cant. | E18: Preț unitar EUR fără TVA | F18: Reducere % | G18: Total EUR fără TVA | H18: Total MDL fără TVA
A19: =IF(B19="","",ROW()-18) | B19: Tractor LS MT1.25 HST FR STAGE V | C19: =IF(B19="","",IFERROR(HYPERLINK(INDEX(Catalog!$B$2:$B$34,MATCH(B19,Catalog!$A$2:$A$34,0)),"Vezi produs"),"")) | D19: 1 | E19: =IF(B19="","",IFERROR(INDEX(Catalog!$C$2:$C$34,MATCH(B19,Catalog!$A$2:$A$34,0)),"nu e în listă")) | G19: =IF(AND(ISNUMBER(D19),ISNUMBER(E19)),ROUND(D19*E19*(1-N(F19)),2),"") | H19: =IF(ISNUMBER(G19),ROUND(G19*$C$9,0),"")
A20: =IF(B20="","",ROW()-18) | C20: =IF(B20="","",IFERROR(HYPERLINK(INDEX(Catalog!$B$2:$B$34,MATCH(B20,Catalog!$A$2:$A$34,0)),"Vezi produs"),"")) | E20: =IF(B20="","",IFERROR(INDEX(Catalog!$C$2:$C$34,MATCH(B20,Catalog!$A$2:$A$34,0)),"nu e în listă")) | G20: =IF(AND(ISNUMBER(D20),ISNUMBER(E20)),ROUND(D20*E20*(1-N(F20)),2),"") | H20: =IF(ISNUMBER(G20),ROUND(G20*$C$9,0),"")
A21: =IF(B21="","",ROW()-18) | C21: =IF(B21="","",IFERROR(HYPERLINK(INDEX(Catalog!$B$2:$B$34,MATCH(B21,Catalog!$A$2:$A$34,0)),"Vezi produs"),"")) | E21: =IF(B21="","",IFERROR(INDEX(Catalog!$C$2:$C$34,MATCH(B21,Catalog!$A$2:$A$34,0)),"nu e în listă")) | G21: =IF(AND(ISNUMBER(D21),ISNUMBER(E21)),ROUND(D21*E21*(1-N(F21)),2),"") | H21: =IF(ISNUMBER(G21),ROUND(G21*$C$9,0),"")
A22: =IF(B22="","",ROW()-18) | C22: =IF(B22="","",IFERROR(HYPERLINK(INDEX(Catalog!$B$2:$B$34,MATCH(B22,Catalog!$A$2:$A$34,0)),"Vezi produs"),"")) | E22: =IF(B22="","",IFERROR(INDEX(Catalog!$C$2:$C$34,MATCH(B22,Catalog!$A$2:$A$34,0)),"nu e în listă")) | G22: =IF(AND(ISNUMBER(D22),ISNUMBER(E22)),ROUND(D22*E22*(1-N(F22)),2),"") | H22: =IF(ISNUMBER(G22),ROUND(G22*$C$9,0),"")
A23: =IF(B23="","",ROW()-18) | C23: =IF(B23="","",IFERROR(HYPERLINK(INDEX(Catalog!$B$2:$B$34,MATCH(B23,Catalog!$A$2:$A$34,0)),"Vezi produs"),"")) | E23: =IF(B23="","",IFERROR(INDEX(Catalog!$C$2:$C$34,MATCH(B23,Catalog!$A$2:$A$34,0)),"nu e în listă")) | G23: =IF(AND(ISNUMBER(D23),ISNUMBER(E23)),ROUND(D23*E23*(1-N(F23)),2),"") | H23: =IF(ISNUMBER(G23),ROUND(G23*$C$9,0),"")
A24: =IF(B24="","",ROW()-18) | C24: =IF(B24="","",IFERROR(HYPERLINK(INDEX(Catalog!$B$2:$B$34,MATCH(B24,Catalog!$A$2:$A$34,0)),"Vezi produs"),"")) | E24: =IF(B24="","",IFERROR(INDEX(Catalog!$C$2:$C$34,MATCH(B24,Catalog!$A$2:$A$34,0)),"nu e în listă")) | G24: =IF(AND(ISNUMBER(D24),ISNUMBER(E24)),ROUND(D24*E24*(1-N(F24)),2),"") | H24: =IF(ISNUMBER(G24),ROUND(G24*$C$9,0),"")
A25: =IF(B25="","",ROW()-18) | C25: =IF(B25="","",IFERROR(HYPERLINK(INDEX(Catalog!$B$2:$B$34,MATCH(B25,Catalog!$A$2:$A$34,0)),"Vezi produs"),"")) | E25: =IF(B25="","",IFERROR(INDEX(Catalog!$C$2:$C$34,MATCH(B25,Catalog!$A$2:$A$34,0)),"nu e în listă")) | G25: =IF(AND(ISNUMBER(D25),ISNUMBER(E25)),ROUND(D25*E25*(1-N(F25)),2),"") | H25: =IF(ISNUMBER(G25),ROUND(G25*$C$9,0),"")
A26: =IF(B26="","",ROW()-18) | C26: =IF(B26="","",IFERROR(HYPERLINK(INDEX(Catalog!$B$2:$B$34,MATCH(B26,Catalog!$A$2:$A$34,0)),"Vezi produs"),"")) | E26: =IF(B26="","",IFERROR(INDEX(Catalog!$C$2:$C$34,MATCH(B26,Catalog!$A$2:$A$34,0)),"nu e în listă")) | G26: =IF(AND(ISNUMBER(D26),ISNUMBER(E26)),ROUND(D26*E26*(1-N(F26)),2),"") | H26: =IF(ISNUMBER(G26),ROUND(G26*$C$9,0),"")
A27: =IF(B27="","",ROW()-18) | C27: =IF(B27="","",IFERROR(HYPERLINK(INDEX(Catalog!$B$2:$B$34,MATCH(B27,Catalog!$A$2:$A$34,0)),"Vezi produs"),"")) | E27: =IF(B27="","",IFERROR(INDEX(Catalog!$C$2:$C$34,MATCH(B27,Catalog!$A$2:$A$34,0)),"nu e în listă")) | G27: =IF(AND(ISNUMBER(D27),ISNUMBER(E27)),ROUND(D27*E27*(1-N(F27)),2),"") | H27: =IF(ISNUMBER(G27),ROUND(G27*$C$9,0),"")
A28: =IF(B28="","",ROW()-18) | C28: =IF(B28="","",IFERROR(HYPERLINK(INDEX(Catalog!$B$2:$B$34,MATCH(B28,Catalog!$A$2:$A$34,0)),"Vezi produs"),"")) | E28: =IF(B28="","",IFERROR(INDEX(Catalog!$C$2:$C$34,MATCH(B28,Catalog!$A$2:$A$34,0)),"nu e în listă")) | G28: =IF(AND(ISNUMBER(D28),ISNUMBER(E28)),ROUND(D28*E28*(1-N(F28)),2),"") | H28: =IF(ISNUMBER(G28),ROUND(G28*$C$9,0),"")
E30: Total fără TVA | G30: =SUM(G19:G28) | H30: =SUM(H19:H28)
E31: ="TVA "&TEXT(CotaTVA,"0%") | G31: =ROUND(G30*CotaTVA,2) | H31: =ROUND(H30*CotaTVA,0)
E32: TOTAL cu TVA | G32: =G30+G31 | H32: =H30+H31
A34: CONDIȚII
B35: Garanție: | C35: 12 luni.
B36: Livrare: | C36: Termenul de livrare în funcție de stocul disponibil.
B37: Finanțare: | C37: Asistență și consultanță calificată pentru aplicarea la sisteme de finanțare și subvenționare.
B38: Service: | C38: Asistență tehnică în 48 de ore.
B39: Suport post-vânzare: | C39: Susținem toți clienții printr-o echipă dedicată de piese și accesorii.
B40: Prețuri: | C40: Prețurile sunt în EUR, fără TVA. Suma în MDL este calculată la cursul din C9.
B41: Condiții de plată:
B43: Întocmit de: | E43: Telefon:
B45: Semnătura:
B47: Apăsați aici sau scanați codul pentru site-ul Ozonteh: ozonteh.net

Sheet Catalog
A1: Denumire | B1: Link produs | C1: Preț final EUR | D1: Preț listă EUR | E1: Preț promo EUR | F1: Link ofertă | G1: Categorie
A2: ='Lista de prețuri'!C8 | B2: https://ozonteh.net/product/tractor-ls-mt1-25-hst-fr-stage-v/ | C2: =IF(ISNUMBER('Lista de prețuri'!E8),'Lista de prețuri'!E8,IF(ISNUMBER('Lista de prețuri'!D8),'Lista de prețuri'!D8,"La cerere")) | D2: ='Lista de prețuri'!D8 | E2: =IF(ISNUMBER('Lista de prețuri'!E8),'Lista de prețuri'!E8,"") | F2: https://docs.google.com/spreadsheets/d/1d-DPcMuOkaZlDNGeg9TxpVeKWLoCmQmcg_WQlKofOYw/edit?usp=sharing | G2: Tractoare LS
A3: ='Lista de prețuri'!C9 | B3: https://ozonteh.net/product/tractor-xj25-mt-fr-stage-v/ | C3: =IF(ISNUMBER('Lista de prețuri'!E9),'Lista de prețuri'!E9,IF(ISNUMBER('Lista de prețuri'!D9),'Lista de prețuri'!D9,"La cerere")) | D3: ='Lista de prețuri'!D9 | E3: =IF(ISNUMBER('Lista de prețuri'!E9),'Lista de prețuri'!E9,"") | F3: https://docs.google.com/spreadsheets/d/1VQUUmNMOugokWzoEBQteocTw_VVBCUisyUYrb1yNTNg/edit?usp=sharing | G3: Tractoare LS
A4: ='Lista de prețuri'!C10 | B4: https://ozonteh.net/product/tractor-mt3-40-mt-cab-stage-v/ | C4: =IF(ISNUMBER('Lista de prețuri'!E10),'Lista de prețuri'!E10,IF(ISNUMBER('Lista de prețuri'!D10),'Lista de prețuri'!D10,"La cerere")) | D4: ='Lista de prețuri'!D10 | E4: =IF(ISNUMBER('Lista de prețuri'!E10),'Lista de prețuri'!E10,"") | F4: https://docs.google.com/spreadsheets/d/1yYM2gIqSNpscZ1f5BRUCLptsh20Yj_aWCqxgiDdFRHI/edit?usp=sharing | G4: Tractoare LS
A5: ='Lista de prețuri'!C11 | B5: https://ozonteh.net/product/tractor-mt3-50-mt-cab-stage-v/ | C5: =IF(ISNUMBER('Lista de prețuri'!E11),'Lista de prețuri'!E11,IF(ISNUMBER('Lista de prețuri'!D11),'Lista de prețuri'!D11,"La cerere")) | D5: ='Lista de prețuri'!D11 | E5: =IF(ISNUMBER('Lista de prețuri'!E11),'Lista de prețuri'!E11,"") | F5: https://docs.google.com/spreadsheets/d/1hwIsvZr-t15z8L8x6ttimy04T5xt7_Om8mN38PicCxE/edit?usp=sharing | G5: Tractoare LS
A6: ='Lista de prețuri'!C12 | B6: https://ozonteh.net/product/tractor-mt3-60-mt-cab-stage-v/ | C6: =IF(ISNUMBER('Lista de prețuri'!E12),'Lista de prețuri'!E12,IF(ISNUMBER('Lista de prețuri'!D12),'Lista de prețuri'!D12,"La cerere")) | D6: ='Lista de prețuri'!D12 | E6: =IF(ISNUMBER('Lista de prețuri'!E12),'Lista de prețuri'!E12,"") | F6: https://docs.google.com/spreadsheets/d/1e4uZ5T07wzVUbhO9i8vLj7ReTvCsVDTt7KYoZ_i_kEU/edit?usp=sharing | G6: Tractoare LS
A7: ='Lista de prețuri'!C13 | B7: https://ozonteh.net/product/tractor-r36i-mt-fr-non-eu/ | C7: =IF(ISNUMBER('Lista de prețuri'!E13),'Lista de prețuri'!E13,IF(ISNUMBER('Lista de prețuri'!D13),'Lista de prețuri'!D13,"La cerere")) | D7: ='Lista de prețuri'!D13 | E7: =IF(ISNUMBER('Lista de prețuri'!E13),'Lista de prețuri'!E13,"") | F7: https://docs.google.com/spreadsheets/d/1bF0osNx7iTzx2rOInxHjgC4tdJ-VqUR4iagR6EDNOow/edit?usp=sharing | G7: Tractoare LS
A8: ='Lista de prețuri'!C14 | B8: https://ozonteh.net/product/tractor-r60-mt-fr-non-eu/ | C8: =IF(ISNUMBER('Lista de prețuri'!E14),'Lista de prețuri'!E14,IF(ISNUMBER('Lista de prețuri'!D14),'Lista de prețuri'!D14,"La cerere")) | D8: ='Lista de prețuri'!D14 | E8: =IF(ISNUMBER('Lista de prețuri'!E14),'Lista de prețuri'!E14,"") | F8: https://docs.google.com/spreadsheets/d/1zmWso-JJ1cTvMqmt0iXACNiYgEGPBAVS7_HjC191RC0/edit?usp=sharing | G8: Tractoare LS
A9: ='Lista de prețuri'!C15 | B9: https://ozonteh.net/product/tractor-r65-mt-cab-non-eu/ | C9: =IF(ISNUMBER('Lista de prețuri'!E15),'Lista de prețuri'!E15,IF(ISNUMBER('Lista de prețuri'!D15),'Lista de prețuri'!D15,"La cerere")) | D9: ='Lista de prețuri'!D15 | E9: =IF(ISNUMBER('Lista de prețuri'!E15),'Lista de prețuri'!E15,"") | F9: https://docs.google.com/spreadsheets/d/1vSn7oGUQqW-85Mfe3gS_XxdNMBYkywPC5ALg2EL10XA/edit?usp=sharing | G9: Tractoare LS
A10: ='Lista de prețuri'!C16 | B10: https://ozonteh.net/product/tractor-xr50-mt-cab-non-eu/ | C10: =IF(ISNUMBER('Lista de prețuri'!E16),'Lista de prețuri'!E16,IF(ISNUMBER('Lista de prețuri'!D16),'Lista de prețuri'!D16,"La cerere")) | D10: ='Lista de prețuri'!D16 | E10: =IF(ISNUMBER('Lista de prețuri'!E16),'Lista de prețuri'!E16,"") | F10: https://docs.google.com/spreadsheets/d/1XFH7SnDTHnhod_jWpoSeXCdjaGhVQHgZlP3eILJ-bIU/edit?usp=sharing | G10: Tractoare LS
A11: ='Lista de prețuri'!C17 | B11: https://ozonteh.net/product/tractor-u60-mt-cab-non-eu/ | C11: =IF(ISNUMBER('Lista de prețuri'!E17),'Lista de prețuri'!E17,IF(ISNUMBER('Lista de prețuri'!D17),'Lista de prețuri'!D17,"La cerere")) | D11: ='Lista de prețuri'!D17 | E11: =IF(ISNUMBER('Lista de prețuri'!E17),'Lista de prețuri'!E17,"") | F11: https://docs.google.com/spreadsheets/d/1Yp2qwXE6ItWGFFv0_QZmK26EA8jzjg0HotoSA-oyxfs/edit?usp=sharing | G11: Tractoare LS
A12: ='Lista de prețuri'!C18 | B12: https://ozonteh.net/product/tractor-xu6168-mt-cab-stage-v/ | C12: =IF(ISNUMBER('Lista de prețuri'!E18),'Lista de prețuri'!E18,IF(ISNUMBER('Lista de prețuri'!D18),'Lista de prețuri'!D18,"La cerere")) | D12: ='Lista de prețuri'!D18 | E12: =IF(ISNUMBER('Lista de prețuri'!E18),'Lista de prețuri'!E18,"") | F12: https://docs.google.com/spreadsheets/d/1rlaXvsPbOROWxPd0MQD5BSPnbHFCkNHQMY3zDutTqKE/edit?usp=sharing | G12: Tractoare LS
A13: ='Lista de prețuri'!C19 | B13: https://ozonteh.net/product/tractor-mt5-73-ps-cab-stage-v/ | C13: =IF(ISNUMBER('Lista de prețuri'!E19),'Lista de prețuri'!E19,IF(ISNUMBER('Lista de prețuri'!D19),'Lista de prețuri'!D19,"La cerere")) | D13: ='Lista de prețuri'!D19 | E13: =IF(ISNUMBER('Lista de prețuri'!E19),'Lista de prețuri'!E19,"") | F13: https://docs.google.com/spreadsheets/d/1MqOtJ4FFtNtOWAlbvtaUiyLpjImXTADH7bqVPMMbD9M/edit?usp=sharing | G13: Tractoare LS
... A15: ='Lista de prețuri'!C21 | B15: https://ozonteh.net/product/tractor-mt7-101-ps-cab-stage-v/ | C15: =IF(ISNUMBER('Lista de prețuri'!E21),'Lista de prețuri'!E21,IF(ISNUMBER('Lista de prețuri'!D21),'Lista de prețuri'!D21,"La cerere")) | D15: ='Lista de prețuri'!D21 | E15: =IF(ISNUMBER('Lista de prețuri'!E21),'Lista de prețuri'!E21,"") | F15: https://docs.google.com/spreadsheets/d/13ONqTTmR2Zf62s0kyweH4SfRjlmGvEhxF_iVzY8fJRk/edit?usp=sharing | G15: Tractoare LS
A16: ='Lista de prețuri'!C23 | B16: https://ozonteh.net/product/set-farmtrac-26-promotia-care-chiar-are-sens/ | C16: =IF(ISNUMBER('Lista de prețuri'!E23),'Lista de prețuri'!E23,IF(ISNUMBER('Lista de prețuri'!D23),'Lista de prețuri'!D23,"La cerere")) | D16: ='Lista de prețuri'!D23 | E16: =IF(ISNUMBER('Lista de prețuri'!E23),'Lista de prețuri'!E23,"") | F16: https://docs.google.com/spreadsheets/d/1qgzd4LLxUb_mJYK4Avn5HDe5M2oDXh6Ixm5YlLvRCPE/edit?gid=1986360129 | G16: Tractoare Farmtrac
A17: ='Lista de prețuri'!C24 | B17: https://ozonteh.net/product/tractor-farmtrac-26-4wd/ | C17: =IF(ISNUMBER('Lista de prețuri'!E24),'Lista de prețuri'!E24,IF(ISNUMBER('Lista de prețuri'!D24),'Lista de prețuri'!D24,"La cerere")) | D17: ='Lista de prețuri'!D24 | E17: =IF(ISNUMBER('Lista de prețuri'!E24),'Lista de prețuri'!E24,"") | F17: https://docs.google.com/spreadsheets/d/11UuSQ0REVekn9_O4LlbyYdEGM0jkslyzGYzYWcpKCsA/edit?usp=sharing | G17: Tractoare Farmtrac
A18: ='Lista de prețuri'!C25 | B18: https://ozonteh.net/product/tractor-farmtrac-26-pro-4wd/ | C18: =IF(ISNUMBER('Lista de prețuri'!E25),'Lista de prețuri'!E25,IF(ISNUMBER('Lista de prețuri'!D25),'Lista de prețuri'!D25,"La cerere")) | D18: ='Lista de prețuri'!D25 | E18: =IF(ISNUMBER('Lista de prețuri'!E25),'Lista de prețuri'!E25,"") | F18: https://docs.google.com/spreadsheets/d/12LTU5OOQ8vHRfnUO9tLrgQl6ZonRziPy30TP1tS44EA/edit?usp=sharing | G18: Tractoare Farmtrac
A19: ='Lista de prețuri'!C26 | B19: https://ozonteh.net/product/tractor-farmtrac-30-4wd/ | C19: =IF(ISNUMBER('Lista de prețuri'!E26),'Lista de prețuri'!E26,IF(ISNUMBER('Lista de prețuri'!D26),'Lista de prețuri'!D26,"La cerere")) | D19: ='Lista de prețuri'!D26 | E19: =IF(ISNUMBER('Lista de prețuri'!E26),'Lista de prețuri'!E26,"") | F19: https://docs.google.com/spreadsheets/d/1c1YdjDr0M2tUXUIhzRnrKfFuJ61_XafDvtS-C4Qv7QE/edit?usp=sharing | G19: Tractoare Farmtrac
A20: ='Lista de prețuri'!C27 | B20: https://ozonteh.net/product/tractor-farmtrac-35-4wd/ | C20: =IF(ISNUMBER('Lista de prețuri'!E27),'Lista de prețuri'!E27,IF(ISNUMBER('Lista de prețuri'!D27),'Lista de prețuri'!D27,"La cerere")) | D20: ='Lista de prețuri'!D27 | E20: =IF(ISNUMBER('Lista de prețuri'!E27),'Lista de prețuri'!E27,"") | F20: https://docs.google.com/spreadsheets/d/17D9ucKOf7YvtwIilnGCYHrFhmblyTEC9WuvuhxU2qaw/edit?usp=sharing | G20: Tractoare Farmtrac
A21: ='Lista de prețuri'!C28 | B21: https://ozonteh.net/product/tractor-farmtrac-35-4wd-revers/ | C21: =IF(ISNUMBER('Lista de prețuri'!E28),'Lista de prețuri'!E28,IF(ISNUMBER('Lista de prețuri'!D28),'Lista de prețuri'!D28,"La cerere")) | D21: ='Lista de prețuri'!D28 | E21: =IF(ISNUMBER('Lista de prețuri'!E28),'Lista de prețuri'!E28,"") | F21: https://docs.google.com/spreadsheets/d/1SvNzZs4N9PmHaDlwd44zFnET_MhjuFZelr8VZJU9VTY/edit?usp=sharing | G21: Tractoare Farmtrac
A22: ='Lista de prețuri'!C29 | B22: https://ozonteh.net/product/tractor-farmtrac-6075n-4wd/ | C22: =IF(ISNUMBER('Lista de prețuri'!E29),'Lista de prețuri'!E29,IF(ISNUMBER('Lista de prețuri'!D29),'Lista de prețuri'!D29,"La cerere")) | D22: ='Lista de prețuri'!D29 | E22: =IF(ISNUMBER('Lista de prețuri'!E29),'Lista de prețuri'!E29,"") | F22: https://docs.google.com/spreadsheets/d/1IUb9-49zi2UGRtt_OIpBtQsSyXH6hq-hNDmekiqXxak/edit?usp=sharing | G22: Tractoare Farmtrac
A23: ='Lista de prețuri'!C30 | B23: https://ozonteh.net/product/tractor-farmtrac-6075n-4wd-cabina/ | C23: =IF(ISNUMBER('Lista de prețuri'!E30),'Lista de prețuri'!E30,IF(ISNUMBER('Lista de prețuri'!D30),'Lista de prețuri'!D30,"La cerere")) | D23: ='Lista de prețuri'!D30 | E23: =IF(ISNUMBER('Lista de prețuri'!E30),'Lista de prețuri'!E30,"") | F23: https://docs.google.com/spreadsheets/d/1osJx0Bfkq65Q9UPr31FDNk9tMTXILP38nSmSWw1goVo/edit?usp=sharing | G23: Tractoare Farmtrac
A24: ='Lista de prețuri'!C32 | C24: =IF(ISNUMBER('Lista de prețuri'!E32),'Lista de prețuri'!E32,IF(ISNUMBER('Lista de prețuri'!D32),'Lista de prețuri'!D32,"La cerere")) | D24: ='Lista de prețuri'!D32 | E24: =IF(ISNUMBER('Lista de prețuri'!E32),'Lista de prețuri'!E32,"") | F24: https://docs.google.com/spreadsheets/d/1OiH8iDBGS1VNKeqDaFMpkKoDRtddIwlhEZLTiaH8xgI/edit?usp=sharing | G24: Tractoare Antonio Carraro
A25: ='Lista de prețuri'!C33 | C25: =IF(ISNUMBER('Lista de prețuri'!E33),'Lista de prețuri'!E33,IF(ISNUMBER('Lista de prețuri'!D33),'Lista de prețuri'!D33,"La cerere")) | D25: ='Lista de prețuri'!D33 | E25: =IF(ISNUMBER('Lista de prețuri'!E33),'Lista de prețuri'!E33,"") | F25: https://docs.google.com/spreadsheets/d/1mp_bwI_tNSfqdDCM9C2kj7ydddWlJOtoKzydAnFkAcY/edit?usp=sharing | G25: Tractoare Antonio Carraro
A26: ='Lista de prețuri'!C34 | B26: https://ozonteh.net/product/tractor-antonio-carraro-trg-9900/ | C26: =IF(ISNUMBER('Lista de prețuri'!E34),'Lista de prețuri'!E34,IF(ISNUMBER('Lista de prețuri'!D34),'Lista de prețuri'!D34,"La cerere")) | D26: ='Lista de prețuri'!D34 | E26: =IF(ISNUMBER('Lista de prețuri'!E34),'Lista de prețuri'!E34,"") | F26: https://docs.google.com/spreadsheets/d/1ho6jccWImpWFiPzRaBn8gBwQGq5JYORdnChAPFiNxhs/edit?usp=sharing | G26: Tractoare Antonio Carraro
A27: ='Lista de prețuri'!C36 | B27: https://ozonteh.net/product/tractor-solis-s16/ | C27: =IF(ISNUMBER('Lista de prețuri'!E36),'Lista de prețuri'!E36,IF(ISNUMBER('Lista de prețuri'!D36),'Lista de prețuri'!D36,"La cerere")) | D27: ='Lista de prețuri'!D36 | E27: =IF(ISNUMBER('Lista de prețuri'!E36),'Lista de prețuri'!E36,"") | F27: https://docs.google.com/spreadsheets/d/14ya2mz7gp8VJtFAB6bhWPSTccHxVuvoZamD9d_GWTcg/edit?usp=sharing | G27: Tractoare Solis
A28: ='Lista de prețuri'!C37 | B28: https://ozonteh.net/product/tractor-solis-s26/ | C28: =IF(ISNUMBER('Lista de prețuri'!E37),'Lista de prețuri'!E37,IF(ISNUMBER('Lista de prețuri'!D37),'Lista de prețuri'!D37,"La cerere")) | D28: ='Lista de prețuri'!D37 | E28: =IF(ISNUMBER('Lista de prețuri'!E37),'Lista de prețuri'!E37,"") | F28: https://docs.google.com/spreadsheets/d/1XZr3NPhTBdEjyPlSGhdTbu_IpugbQXk408HnlXCjWVI/edit?usp=sharing | G28: Tractoare Solis
A29: ='Lista de prețuri'!C38 | B29: https://ozonteh.net/product/tractor-solis-s26-extra/ | C29: =IF(ISNUMBER('Lista de prețuri'!E38),'Lista de prețuri'!E38,IF(ISNUMBER('Lista de prețuri'!D38),'Lista de prețuri'!D38,"La cerere")) | D29: ='Lista de prețuri'!D38 | E29: =IF(ISNUMBER('Lista de prețuri'!E38),'Lista de prețuri'!E38,"") | F29: https://docs.google.com/spreadsheets/d/1EbF-n6IP4V1LgoAw5lqCzOsmcEABbfXo9aSioJJSEik/edit?usp=sharing | G29: Tractoare Solis
A30: ='Lista de prețuri'!C39 | B30: https://ozonteh.net/product/tractor-solis-s26-shuttle-xl/ | C30: =IF(ISNUMBER('Lista de prețuri'!E39),'Lista de prețuri'!E39,IF(ISNUMBER('Lista de prețuri'!D39),'Lista de prețuri'!D39,"La cerere")) | D30: ='Lista de prețuri'!D39 | E30: =IF(ISNUMBER('Lista de prețuri'!E39),'Lista de prețuri'!E39,"") | F30: https://docs.google.com/spreadsheets/d/1Xto9qKPfwfMONUAIAX9y-9dh5JDfYThy33vgktdgAoU/edit?usp=sharing | G30: Tractoare Solis
A31: ='Lista de prețuri'!C40 | B31: https://ozonteh.net/product/tractor-solis-s30/ | C31: =IF(ISNUMBER('Lista de prețuri'!E40),'Lista de prețuri'!E40,IF(ISNUMBER('Lista de prețuri'!D40),'Lista de prețuri'!D40,"La cerere")) | D31: ='Lista de prețuri'!D40 | E31: =IF(ISNUMBER('Lista de prețuri'!E40),'Lista de prețuri'!E40,"") | F31: https://docs.google.com/spreadsheets/d/1N2nn0zaUJx3Pk72dX0B_dhG40wPfpD4WmGWUpmg5KBE/edit?usp=sharing | G31: Tractoare Solis
A32: ='Lista de prețuri'!C41 | B32: https://ozonteh.net/product/tractor-solis-s32/ | C32: =IF(ISNUMBER('Lista de prețuri'!E41),'Lista de prețuri'!E41,IF(ISNUMBER('Lista de prețuri'!D41),'Lista de prețuri'!D41,"La cerere")) | D32: ='Lista de prețuri'!D41 | E32: =IF(ISNUMBER('Lista de prețuri'!E41),'Lista de prețuri'!E41,"") | F32: https://docs.google.com/spreadsheets/d/1xxVx9Ko6C-ytFDG3tAnjsR0YajCrOvVoS7NK8PVJcoc/edit?usp=sharing | G32: Tractoare Solis
A33: ='Lista de prețuri'!C42 | B33: https://ozonteh.net/product/tractor-solis-90n/ | C33: =IF(ISNUMBER('Lista de prețuri'!E42),'Lista de prețuri'!E42,IF(ISNUMBER('Lista de prețuri'!D42),'Lista de prețuri'!D42,"La cerere")) | D33: ='Lista de prețuri'!D42 | E33: =IF(ISNUMBER('Lista de prețuri'!E42),'Lista de prețuri'!E42,"") | F33: https://docs.google.com/spreadsheets/d/1hyt_2iQkL4oARzU_Ixa8ZIVfrL1Zfc3HH7Drmm26KBU/edit?usp=sharing | G33: Tractoare Solis
A34: ='Lista de prețuri'!C43 | B34: https://ozonteh.net/product/tractor-solis-90rx/ | C34: =IF(ISNUMBER('Lista de prețuri'!E43),'Lista de prețuri'!E43,IF(ISNUMBER('Lista de prețuri'!D43),'Lista de prețuri'!D43,"La cerere")) | D34: ='Lista de prețuri'!D43 | E34: =IF(ISNUMBER('Lista de prețuri'!E43),'Lista de prețuri'!E43,"") | F34: https://docs.google.com/spreadsheets/d/10h2WOGrFCXcbxJoBjbpbDlvyysu5tGFME1b1GT_Q_y4/edit?usp=sharing | G34: Tractoare Solis
